const x = 10

try {
    x = 15
} catch (err) {
    console.log(`Erro: ${err}`)
}